<?xml version="1.0" encoding="UTF-8"?>
<testng-results skipped="0" failed="1" total="1" passed="0">
  <reporter-output>
  </reporter-output>
  <suite name="Default suite" duration-ms="25106" started-at="2015-05-24T15:36:55Z" finished-at="2015-05-24T15:37:20Z">
    <groups>
    </groups>
    <test name="Default test" duration-ms="25106" started-at="2015-05-24T15:36:55Z" finished-at="2015-05-24T15:37:20Z">
      <class name="selenium.tests.SuccessRegistration">
        <test-method status="PASS" signature="beforeTest()[pri:0, instance:selenium.tests.SuccessRegistration@11531931]" name="beforeTest" is-config="true" duration-ms="18211" started-at="2015-05-24T18:36:55Z" finished-at="2015-05-24T18:37:13Z">
          <reporter-output>
          </reporter-output>
        </test-method> <!-- beforeTest -->
        <test-method status="FAIL" signature="registerFlow()[pri:0, instance:selenium.tests.SuccessRegistration@11531931]" name="registerFlow" duration-ms="6543" started-at="2015-05-24T18:37:13Z" finished-at="2015-05-24T18:37:20Z">
          <exception class="java.lang.AssertionError">
            <message>
              <![CDATA[expected [Ваша учётная запись активирована. Вы можете войти.] but found [Account was successfully updated.]]]>
            </message>
            <full-stacktrace>
              <![CDATA[java.lang.AssertionError: expected [Ваша учётная запись активирована. Вы можете войти.] but found [Account was successfully updated.]
	at org.testng.Assert.fail(Assert.java:94)
	at org.testng.Assert.failNotEquals(Assert.java:494)
	at org.testng.Assert.assertEquals(Assert.java:123)
	at org.testng.Assert.assertEquals(Assert.java:176)
	at org.testng.Assert.assertEquals(Assert.java:186)
	at selenium.tests.SuccessRegistration.registerFlow(SuccessRegistration.java:42)
	at sun.reflect.NativeMethodAccessorImpl.invoke0(Native Method)
	at sun.reflect.NativeMethodAccessorImpl.invoke(Unknown Source)
	at sun.reflect.DelegatingMethodAccessorImpl.invoke(Unknown Source)
	at java.lang.reflect.Method.invoke(Unknown Source)
	at org.testng.internal.MethodInvocationHelper.invokeMethod(MethodInvocationHelper.java:84)
	at org.testng.internal.Invoker.invokeMethod(Invoker.java:714)
	at org.testng.internal.Invoker.invokeTestMethod(Invoker.java:901)
	at org.testng.internal.Invoker.invokeTestMethods(Invoker.java:1231)
	at org.testng.internal.TestMethodWorker.invokeTestMethods(TestMethodWorker.java:127)
	at org.testng.internal.TestMethodWorker.run(TestMethodWorker.java:111)
	at org.testng.TestRunner.privateRun(TestRunner.java:767)
	at org.testng.TestRunner.run(TestRunner.java:617)
	at org.testng.SuiteRunner.runTest(SuiteRunner.java:334)
	at org.testng.SuiteRunner.runSequentially(SuiteRunner.java:329)
	at org.testng.SuiteRunner.privateRun(SuiteRunner.java:291)
	at org.testng.SuiteRunner.run(SuiteRunner.java:240)
	at org.testng.SuiteRunnerWorker.runSuite(SuiteRunnerWorker.java:52)
	at org.testng.SuiteRunnerWorker.run(SuiteRunnerWorker.java:86)
	at org.testng.TestNG.runSuitesSequentially(TestNG.java:1224)
	at org.testng.TestNG.runSuitesLocally(TestNG.java:1149)
	at org.testng.TestNG.run(TestNG.java:1057)
	at org.testng.remote.RemoteTestNG.run(RemoteTestNG.java:111)
	at org.testng.remote.RemoteTestNG.initAndRun(RemoteTestNG.java:204)
	at org.testng.remote.RemoteTestNG.main(RemoteTestNG.java:175)
]]>
            </full-stacktrace>
          </exception> <!-- java.lang.AssertionError -->
          <reporter-output>
          </reporter-output>
        </test-method> <!-- registerFlow -->
        <test-method status="PASS" signature="afterTest()[pri:0, instance:selenium.tests.SuccessRegistration@11531931]" name="afterTest" is-config="true" duration-ms="343" started-at="2015-05-24T18:37:20Z" finished-at="2015-05-24T18:37:20Z">
          <reporter-output>
          </reporter-output>
        </test-method> <!-- afterTest -->
      </class> <!-- selenium.tests.SuccessRegistration -->
    </test> <!-- Default test -->
  </suite> <!-- Default suite -->
</testng-results>
